Workbook

Sheet 2-Sep
F1: 45902 | M1: Vehicle Trip Plan | T1: Actual Dispatch | AE1: GAP
M2: T-1 | N2: T-2 | O2: T-3 | P2: T-4 | Q2: T-5 | R2: T-6 | T2: T-1 | U2: T-2 | V2: T-3 | W2: T-4 | X2: T-5 | Y2: T-6 | Z2: T-7 | AA2: T-8 | AB2: T=9 | AD2: Vehicle No. | AE2: T-1 | AF2: T-2 | AG2: T-3 | AH2: T-4 | AI2: T-5 | AJ2: T-6
A3: Customer Part No. | B3: Description | C3: Material Code | D3: Stocking Norm | E3: Customer's Todays Plan | F3: Stock at Customer End | G3: Stock on Wheel | H3: Dispatch Requirement | I3: Short against Requirement | J3: Total Plan | K3: Total Actual | L3: No Of Trolley | M3: 6 | N3: 6 | O3: 6 | P3: 6 | Q3: 6 | R3: 6 | S3: 36 | T3: 6 | U3: 3 | V3: 5 | W3: 4 | X3: 5 | Y3: 5 | AC3: 28 | AE3: 0 | AF3: -3 | AG3: -4 | AH3: 4 | AI3: -2 | AJ3: -8
L4: Vehicle No | AD4: Out Time
AD5: In time
L6: Time | M6: 0.27083333 | N6: 0.375 | O6: 0.52083333 | P6: 0.64583333 | Q6: 0.75 | R6: 0.83333333 | T6: 0.27083333 | U6: 0.375 | V6: 0.48819444 | W6: 0.66458333 | X6: 0.75 | Y6: 0.79166667 | AD6: Actual | AE6: 0.27083333 | AF6: 0.29166667 | AG6: 0.40625 | AH6: 0.46875 | AI6: 0.61458333
A7: 542468900289ZZ | B7: Cluster GB | C7: 753000360-200 | D7: 184 | E7: 0 | F7: 112 | H7: 72 | I7: 0 | J7: 96 | K7: 0 | O7: 96 | AD7: 0 | AE7: 0 | AF7: 0 | AG7: -96 | AH7: -96 | AI7: -96 | AJ7: -96
A8: 542468900289ZV | B8: Cluster ULS | C8: 753000360-324 | D8: 199 | E8: 350 | F8: 104 | H8: 445 | I8: 61 | J8: 384 | K8: 0 | O8: 96 | P8: 96 | Q8: 192 | V8: 288 | X8: 96 | AD8: 0 | AE8: 0 | AF8: 0 | AG8: -96 | AH8: -192 | AI8: -384 | AJ8: -384
A9: 542468900289ZQ | B9: Cluster Titan Brown | C9: 753000360-011 | D9: 168 | E9: 40 | F9: 126 | H9: 82 | I9: 0 | J9: 96 | K9: 0 | P9: 96 | AD9: 0 | AE9: 0 | AF9: 0 | AG9: 0 | AH9: -96 | AI9: -96 | AJ9: -96
A10: 542468910103CC | B10: Console LLG | C10: 753000370-009 | D10: 200 | E10: 14 | F10: 240 | H10: 0 | I10: 0 | J10: 0 | K10: 0 | AD10: 0 | AE10: 0 | AF10: 0 | AG10: 0 | AH10: 0 | AI10: 0 | AJ10: 0
A11: 542468910103D1 | B11: Console KLG | C11: 753000370-452 | D11: 260 | E11: 294 | F11: 241 | H11: 313 | I11: 53 | J11: 260 | K11: 0 | O11: 130 | P11: 130 | V11: 130 | X11: 130 | AD11: 0 | AE11: 0 | AF11: 0 | AG11: -130 | AH11: -260 | AI11: -260 | AJ11: -260
A12: 542569500104D1 | B12: HMSL KLG | C12: 630131090-452 | D12: 140 | E12: 0 | F12: 200 | H12: 0 | I12: 0 | J12: 0 | K12: 0 | AD12: 0 | AE12: 0 | AF12: 0 | AG12: 0 | AH12: 0 | AI12: 0 | AJ12: 0
A13: 542569500104CC | B13: HMSL LLG | C13: 630131090 | D13: 140 | E13: 40 | F13: 160 | H13: 20 | I13: 20 | J13: 0 | K13: 0 | AD13: 0 | AE13: 0 | AF13: 0 | AG13: 0 | AH13: 0 | AI13: 0 | AJ13: 0
A14: 542469500102D1 | B14: 102D1 | C14: 586118320-083 | D14: 42 | E14: 73 | F14: 14 | H14: 101 | I14: 3 | J14: 98 | K14: 0 | M14: 14 | N14: 14 | O14: 14 | P14: 14 | Q14: 14 | R14: 28 | T14: 14 | U14: 14 | V14: 14 | W14: 14 | X14: 14 | AD14: 0 | AE14: -14 | AF14: -28 | AG14: -42 | AH14: -56 | AI14: -70 | AJ14: -98
A15: 542469500118D1 | B15: 118D1 | C15: 586688560-083 | D15: 28 | E15: 6 | F15: 33 | H15: 1 | I15: 0 | J15: 14 | K15: 0 | O15: 14 | U15: 14 | AD15: 0 | AE15: 0 | AF15: 0 | AG15: -14 | AH15: -14 | AI15: -14 | AJ15: -14
A16: 542469500119D1 | B16: 119D1 | C16: 586688570-083 | D16: 84 | E16: 277 | F16: 50 | H16: 311 | I16: 3 | J16: 308 | K16: 0 | M16: 14 | N16: 42 | O16: 56 | P16: 70 | Q16: 70 | R16: 56 | T16: 14 | U16: 42 | V16: 42 | W16: 42 | X16: 56 | Y16: 56 | AD16: 0 | AE16: -14 | AF16: -56 | AG16: -112 | AH16: -182 | AI16: -252 | AJ16: -308
A17: 542469500120D1 | B17: 120D1 | C17: 586450180-083 | D17: 28 | E17: 14 | F17: 28 | H17: 14 | I17: 0 | J17: 28 | K17: 0 | M17: 14 | N17: 14 | T17: 14 | AD17: 0 | AE17: -14 | AF17: -28 | AG17: -28 | AH17: -28 | AI17: -28 | AJ17: -28
A18: 546769500115D1 | B18: 115D1 | C18: 586688580-083 | D18: 0 | E18: 0 | F18: 0 | H18: 0 | I18: 0 | J18: 0 | K18: 0 | AD18: 0 | AE18: 0 | AF18: 0 | AG18: 0 | AH18: 0 | AI18: 0 | AJ18: 0
A19: 546769500133D1 | B19: 133D1 | C19: 586688590-083 | D19: 28 | E19: 0 | F19: 14 | H19: 14 | I19: 0 | J19: 14 | K19: 0 | M19: 14 | T19: 14 | AD19: 0 | AE19: -14 | AF19: -14 | AG19: -14 | AH19: -14 | AI19: -14 | AJ19: -14
A20: 546769500134D1 | B20: 134D1 | C20: 586688600-083 | D20: 28 | E20: 12 | F20: 36 | H20: 4 | I20: 0 | J20: 28 | K20: 0 | M20: 14 | N20: 14 | T20: 14 | Y20: 14 | AD20: 0 | AE20: -14 | AF20: -28 | AG20: -28 | AH20: -28 | AI20: -28 | AJ20: -28
A21: 546769500135D1 | B21: 135D1 | C21: 586688610-083 | D21: 28 | E21: 8 | F21: 38 | H21: 0 | I21: 0 | J21: 14 | K21: 0 | M21: 14 | W21: 14 | AD21: 0 | AE21: -14 | AF21: -14 | AG21: -14 | AH21: -14 | AI21: -14 | AJ21: -14
A22: 542474700122 | B22: TAIL GATE | C22: 631161170-220 | D22: 50 | E22: 0 | F22: 55 | H22: 0 | I22: 0 | J22: 0 | K22: 0 | AD22: 0 | AE22: 0 | AF22: 0 | AG22: 0 | AH22: 0 | AI22: 0 | AJ22: 0
A23: 542463700115 | B23: SIDE RH | C23: 631161221-220 | D23: 50 | E23: 0 | F23: 60 | H23: 0 | I23: 0 | J23: 0 | K23: 0 | AD23: 0 | AE23: 0 | AF23: 0 | AG23: 0 | AH23: 0 | AI23: 0 | AJ23: 0
A24: 542463700114 | B24: SIDE LH | C24: 631161222-220 | D24: 50 | E24: 0 | F24: 42 | H24: 8 | I24: 8 | J24: 0 | K24: 0 | AD24: 0 | AE24: 0 | AF24: 0 | AG24: 0 | AH24: 0 | AI24: 0 | AJ24: 0
A25: 542472700140 | B25: FR RUBRAIL RH | C25: 631161181-220 | D25: 50 | E25: 0 | F25: 60 | H25: 0 | I25: 0 | J25: 0 | K25: 0 | AD25: 0 | AE25: 0 | AF25: 0 | AG25: 0 | AH25: 0 | AI25: 0 | AJ25: 0
A26: 542472700139 | B26: FR RUBRAIL LH | C26: 631161182-220 | D26: 50 | E26: 0 | F26: 40 | H26: 10 | I26: 10 | J26: 0 | K26: 0 | AD26: 0 | AE26: 0 | AF26: 0 | AG26: 0 | AH26: 0 | AI26: 0 | AJ26: 0
A27: 542473700124 | B27: RR RUBRAIL RH | C27: 631161191-220 | D27: 50 | E27: 0 | F27: 35 | H27: 15 | I27: 15 | J27: 0 | K27: 0 | AD27: 0 | AE27: 0 | AF27: 0 | AG27: 0 | AH27: 0 | AI27: 0 | AJ27: 0
A28: 542473700123 | B28: RR RUBRAIL LH | C28: 631161192-220 | D28: 50 | E28: 0 | F28: 36 | H28: 14 | I28: 14 | J28: 0 | K28: 0 | AD28: 0 | AE28: 0 | AF28: 0 | AG28: 0 | AH28: 0 | AI28: 0 | AJ28: 0
A29: 542488100121 | B29: FR WHEEL ARCH RH | C29: 631161201-220 | D29: 50 | E29: 0 | F29: 250 | H29: 0 | I29: 0 | J29: 0 | K29: 0 | AD29: 0 | AE29: 0 | AF29: 0 | AG29: 0 | AH29: 0 | AI29: 0 | AJ29: 0
A30: 542488100120 | B30: FR WHEEL ARCH LH | C30: 631161202-220 | D30: 50 | E30: 0 | F30: 50 | H30: 0 | I30: 0 | J30: 0 | K30: 0 | AD30: 0 | AE30: 0 | AF30: 0 | AG30: 0 | AH30: 0 | AI30: 0 | AJ30: 0
A31: 542488100123 | B31: RR WHEEL ARCH RH | C31: 631161211-220 | D31: 50 | E31: 0 | F31: 70 | H31: 0 | I31: 0 | J31: 0 | K31: 0 | AD31: 0 | AE31: 0 | AF31: 0 | AG31: 0 | AH31: 0 | AI31: 0 | AJ31: 0
A32: 542488100122 | B32: RR WHEEL ARCH LH | C32: 631161212-220 | D32: 50 | E32: 0 | F32: 30 | H32: 20 | I32: 20 | J32: 0 | K32: 0 | AD32: 0 | AE32: 0 | AF32: 0 | AG32: 0 | AH32: 0 | AI32: 0 | AJ32: 0
A33: 542490600102 | B33: ROOF RAIL RH | C33: 631122171-010 | D33: 50 | E33: 0 | F33: 40 | H33: 10 | I33: 10 | J33: 0 | K33: 0 | AD33: 0 | AE33: 0 | AF33: 0 | AG33: 0 | AH33: 0 | AI33: 0 | AJ33: 0
A34: 542490600101 | B34: ROOF RAIL LH | C34: 631122172-010 | D34: 50 | E34: 0 | F34: 40 | H34: 10 | I34: 10 | J34: 0 | K34: 0 | AD34: 0 | AE34: 0 | AF34: 0 | AG34: 0 | AH34: 0 | AI34: 0 | AJ34: 0
J35: 1.625 | K35: 0 | M35: 0.25 | N35: 0.33333333 | O35: 0.45833333 | P35: 0.58333333 | T35: 0.25 | U35: 0.40416667 | V35: 0.47638889 | W35: 0.56458333 | X35: 0.70833333 | AD35: Actual | AE35: 0.27083333
A36: 546469500102ZX | B36: 102ZX | C36: 587136190-083 | D36: 80 | E36: 179 | F36: 12 | H36: 247 | I36: 0 | J36: 248 | K36: 0 | M36: 92 | N36: 28 | O36: 48 | P36: 80 | T36: 92 | U36: 28 | V36: 28 | W36: 32 | X36: 28 | AD36: 0 | AE36: -92 | AF36: -120 | AG36: -168 | AH36: -248 | AI36: -248 | AJ36: -248
A37: 546469500109ZY | B37: 109ZY | C37: 587136180-083 | D37: 32 | E37: 12 | F37: 46 | H37: 0 | I37: 0 | J37: 0 | K37: 0 | AD37: 0 | AE37: 0 | AF37: 0 | AG37: 0 | AH37: 0 | AI37: 0 | AJ37: 0
A38: 546469500114ZY | B38: 114ZY | C38: 587011990-083 | D38: 64 | E38: 8 | F38: 146 | H38: 0 | I38: 0 | J38: 0 | K38: 0 | AD38: 0 | AE38: 0 | AF38: 0 | AG38: 0 | AH38: 0 | AI38: 0 | AJ38: 0
A39: 546469500114ZZ | B39: 114ZZ | C39: 587011990-220 | D39: 32 | E39: 20 | F39: 51 | H39: 1 | I39: 0 | J39: 48 | K39: 0 | N39: 16 | O39: 32 | U39: 16 | V39: 16 | AD39: 0 | AE39: 0 | AF39: -16 | AG39: -48 | AH39: -48 | AI39: -48 | AJ39: -48
A40: 546469500102ZZ | B40: 102ZZ | C40: 587136190-220 | D40: 32 | E40: 17 | F40: 29 | H40: 20 | I40: 4 | J40: 16 | K40: 0 | L40: - | P40: 16 | W40: 12 | AD40: 0 | AE40: 0 | AF40: 0 | AG40: 0 | AH40: -16 | AI40: -16 | AJ40: -16
...

Sheet 02092025
C1: 45902 | H1: Vehicle Trip Plan | O1: Actual Dispatch
H2: T-1 | I2: T-2 | J2: T-3 | K2: T-4 | L2: T-5 | M2: T-6 | N2: T-7 | O2: T-1 | P2: T-2 | Q2: T-3 | R2: T-4 | S2: T-5 | T2: T-6 | U2: T-7 | V2: T-8
A3: Customer Part No. | B3: Description | C3: Material Code | D3: Customer's Todays Plan | E3: Vehicle No | F3: Total Plan | G3: Total Actual | H3: 0 | I3: 0 | J3: 0 | K3: 0 | L3: 0 | M3: 0 | N3: 0 | O3: 0 | P3: 0 | Q3: 0 | R3: 0 | S3: 0 | T3: 0 | U3: 0
E4: Intime
E5: Out Time
E6: CE open STK | H6: 0.27083333 | I6: 0.375 | J6: 0.52083333 | K6: 0.64583333 | L6: 0.75 | M6: 0.83333333 | N6: 0 | O6: 0.27083333 | P6: 0.375 | Q6: 0.48819444 | R6: 0.66458333 | S6: 0.75 | T6: 0.79166667 | U6: 0
A7: 542468900289ZZ | B7: Cluster GB | C7: 753000360-200 | D7: 0 | E7: 112 | F7: 96 | G7: 0 | H7: 0 | I7: 0 | J7: 0 | K7: 0 | L7: 96 | M7: 0 | N7: 0 | U7: 0
A8: 542468900289ZV | B8: Cluster ULS | C8: 753000360-324 | D8: 350 | E8: 192 | F8: 384 | G8: 0 | H8: 0 | I8: 0 | J8: 0 | K8: 0 | L8: 96 | M8: 96 | N8: 192 | Q8: 288 | S8: 96 | U8: 0
A9: 542468900289ZQ | B9: Cluster Titan Brown | C9: 753000360-011 | D9: 40 | E9: 40 | F9: 96 | G9: 0 | H9: 0 | I9: 0 | J9: 0 | K9: 0 | L9: 0 | M9: 96 | N9: 0 | U9: 0
A10: 542468910103CC | B10: Console LLG | C10: 753000370-009 | D10: 14 | E10: 240 | F10: 0 | G10: 0 | H10: 0 | I10: 0 | J10: 0 | K10: 0 | L10: 0 | M10: 0 | N10: 0 | U10: 0
A11: 542468910103D1 | B11: Console KLG | C11: 753000370-452 | D11: 294 | E11: 130 | F11: 260 | G11: 0 | H11: 0 | I11: 0 | J11: 0 | K11: 0 | L11: 130 | M11: 130 | N11: 0 | Q11: 130 | S11: 130 | U11: 0
A12: 542569500104D1 | B12: HMSL KLG | C12: 630131090-452 | D12: 0 | E12: 200 | F12: 0 | G12: 0 | H12: 0 | I12: 0 | J12: 0 | K12: 0 | L12: 0 | M12: 0 | N12: 0 | U12: 0
A13: 542569500104CC | B13: HMSL LLG | C13: 630131090 | D13: 40 | E13: 40 | F13: 0 | G13: 0 | H13: 0 | I13: 0 | J13: 0 | K13: 0 | L13: 0 | M13: 0 | N13: 0 | U13: 0
A14: 542469500102D1 | B14: 102D1 | C14: 586118320-083 | D14: 73 | E14: 45 | F14: 70 | G14: 0 | H14: 0 | I14: 0 | J14: 14 | K14: 14 | L14: 14 | M14: 14 | N14: 14 | O14: 14 | P14: 14 | Q14: 14 | R14: 14 | S14: 14 | U14: 0
A15: 542469500118D1 | B15: 118D1 | C15: 586688560-083 | D15: 6 | E15: 10 | F15: 14 | G15: 0 | H15: 0 | I15: 0 | J15: 0 | K15: 0 | L15: 14 | M15: 0 | N15: 0 | P15: 14 | U15: 0
A16: 542469500119D1 | B16: 119D1 | C16: 586688570-083 | D16: 277 | E16: 20 | F16: 252 | G16: 0 | H16: 0 | I16: 0 | J16: 14 | K16: 42 | L16: 56 | M16: 70 | N16: 70 | O16: 14 | P16: 42 | Q16: 42 | R16: 42 | S16: 56 | T16: 56 | U16: 0
A17: 542469500120D1 | B17: 120D1 | C17: 586450180-083 | D17: 14 | E17: 22 | F17: 28 | G17: 0 | H17: 0 | I17: 0 | J17: 14 | K17: 14 | L17: 0 | M17: 0 | N17: 0 | O17: 14 | U17: 0
A18: 546769500115D1 | B18: 115D1 | C18: 586688580-083 | D18: 0 | E18: 0 | F18: 0 | G18: 0 | H18: 0 | I18: 0 | J18: 0 | K18: 0 | L18: 0 | M18: 0 | N18: 0 | U18: 0
A19: 546769500133D1 | B19: 133D1 | C19: 586688590-083 | D19: 0 | E19: 15 | F19: 14 | G19: 0 | H19: 0 | I19: 0 | J19: 14 | K19: 0 | L19: 0 | M19: 0 | N19: 0 | O19: 14 | U19: 0
A20: 546769500134D1 | B20: 134D1 | C20: 586688600-083 | D20: 12 | E20: 22 | F20: 28 | G20: 0 | H20: 0 | I20: 0 | J20: 14 | K20: 14 | L20: 0 | M20: 0 | N20: 0 | O20: 14 | T20: 14 | U20: 0
A21: 546769500135D1 | B21: 135D1 | C21: 586688610-083 | D21: 8 | E21: 22 | F21: 14 | G21: 0 | H21: 0 | I21: 0 | J21: 14 | K21: 0 | L21: 0 | M21: 0 | N21: 0 | R21: 14 | U21: 0
A22: Customer Part No. | B22: Description | C22: Material Code | D22: Customer's Todays Plan | E22: CE open STK | F22: Total Plan | G22: Total Actual | H22: Vehicle Trip Plan | O22: Actual Dispatch
H23: T-1 | I23: T-2 | J23: T-3 | K23: T-4 | L23: T-5 | M23: T-6 | N23: T-7 | O23: T-1 | P23: T-2 | Q23: T-3 | R23: T-4 | S23: T-5 | T23: T-6 | U23: T-7
O24: 0.25 | P24: 0.40416667 | Q24: 0.47638889 | R24: 0.56458333 | S24: 0.70833333
A25: 546469500102ZX | B25: 102ZX | C25: 587136190-083 | D25: 179 | E25: 12 | H25: 0 | I25: 0 | J25: 92 | K25: 28 | L25: 48 | M25: 80 | N25: 0 | O25: 92 | P25: 28 | Q25: 28 | R25: 32 | S25: 28 | T25: 0 | U25: 0 | W25: 0
A26: 546469500109ZY | B26: 109ZY | C26: 587136180-083 | D26: 12 | E26: 46 | F26: 0 | G26: 0 | H26: 0 | I26: 0 | J26: 0 | K26: 0 | L26: 0 | M26: 0 | N26: 0 | T26: 0 | U26: 0 | W26: 0
A27: 546469500114ZY | B27: 114ZY | C27: 587011990-083 | D27: 8 | E27: 146 | F27: 0 | G27: 0 | H27: 0 | I27: 0 | J27: 0 | K27: 0 | L27: 0 | M27: 0 | N27: 0 | T27: 0 | U27: 0 | W27: 0
A28: 546469500114ZZ | B28: 114ZZ | C28: 587011990-220 | D28: 20 | E28: 51 | F28: 48 | G28: 0 | H28: 0 | I28: 0 | J28: 0 | K28: 16 | L28: 32 | M28: 0 | N28: 0 | P28: 16 | Q28: 16 | T28: 0 | U28: 0 | W28: 0
A29: 546469500102ZZ | B29: 102ZZ | C29: 587136190-220 | D29: 17 | E29: 29 | F29: 16 | G29: 0 | H29: 0 | I29: - | J29: 0 | K29: 0 | L29: 0 | M29: 16 | N29: 0 | R29: 12 | T29: 0 | U29: 0 | W29: 0

Sheet 03092025 (2)
C1: 45903 | H1: Vehicle Trip Plan | O1: Actual Dispatch
H2: T-1 | I2: T-2 | J2: T-3 | K2: T-4 | L2: T-5 | M2: T-6 | N2: T-7 | O2: T-1 | P2: T-2 | Q2: T-3 | R2: T-4 | S2: T-5 | T2: T-6 | U2: T-7 | V2: T-8
A3: Customer Part No. | B3: Description | C3: Material Code | D3: Customer's Todays Plan | E3: Vehicle No | F3: Total Plan | G3: Total Actual | H3: 0 | I3: 0 | J3: 0 | K3: 0 | L3: 0 | M3: 0 | N3: 0 | O3: 0 | P3: 0 | Q3: 0 | R3: 0 | S3: 0 | T3: 0 | U3: 0
E4: Intime
E5: Out Time
E6: CE open STK | H6: 0.27083333 | I6: 0.375 | J6: 0.5 | K6: 0.64583333 | L6: 0.75 | M6: 0 | O6: 0.27083333 | P6: 0.42083333 | Q6: 0.49583333 | R6: 0.70138889 | S6: 0.80555556 | T6: 0.90277778 | U6: 0
A7: 542468900289ZZ | B7: Cluster GB | C7: 753000360-200 | D7: 13 | E7: 108 | F7: 0 | G7: 0 | H7: 0 | I7: 0 | J7: 0 | K7: 0 | L7: 0 | M7: 0 | N7: 0 | O7: 0 | P7: 0 | Q7: 0 | R7: 0 | S7: 0 | T7: 0 | U7: 0
A8: 542468900289ZV | B8: Cluster ULS | C8: 753000360-324 | D8: 299 | E8: 192 | F8: 576 | G8: 273 | H8: 0 | I8: 96 | J8: 192 | K8: 192 | L8: 96 | M8: 0 | N8: 0 | O8: 0 | P8: 61 | Q8: 20 | R8: 96 | S8: 96 | T8: 0 | U8: 0
A9: 542468900289ZQ | B9: Cluster Titan Brown | C9: 753000360-011 | D9: 28 | E9: 40 | F9: 96 | G9: 96 | H9: 0 | I9: 96 | J9: 0 | K9: 0 | L9: 0 | M9: 0 | N9: 0 | O9: 0 | P9: 96 | Q9: 0 | R9: 0 | S9: 0 | T9: 0 | U9: 0
A10: 542468910103CC | B10: Console LLG | C10: 753000370-009 | D10: 4 | E10: 240 | F10: 0 | G10: 0 | H10: 0 | I10: 0 | J10: 0 | K10: 0 | L10: 0 | M10: 0 | N10: 0 | O10: 0 | P10: 0 | Q10: 0 | R10: 0 | S10: 0 | T10: 0 | U10: 0
A11: 542468910103D1 | B11: Console KLG | C11: 753000370-452 | D11: 233 | E11: 130 | F11: 0 | G11: 260 | H11: 0 | I11: 0 | J11: 0 | K11: 0 | L11: 0 | M11: 0 | N11: 0 | O11: 0 | P11: 0 | Q11: 0 | R11: 0 | S11: 260 | T11: 0 | U11: 0
A12: 542569500104D1 | B12: HMSL KLG | C12: 630131090-452 | D12: 0 | E12: 200 | F12: 0 | G12: 0 | H12: 0 | I12: 0 | J12: 0 | K12: 0 | L12: 0 | M12: 0 | N12: 0 | O12: 0 | P12: 0 | Q12: 0 | R12: 0 | S12: 0 | T12: 0 | U12: 0
A13: 542569500104CC | B13: HMSL LLG | C13: 630131090 | D13: 28 | E13: 40 | F13: 0 | G13: 0 | H13: 0 | I13: 0 | J13: 0 | K13: 0 | L13: 0 | M13: 0 | N13: 0 | O13: 0 | P13: 0 | Q13: 0 | R13: 0 | S13: 0 | T13: 0 | U13: 0
A14: 542469500102D1 | B14: 102D1 | C14: 586118320-083 | D14: 82 | E14: 45 | F14: 70 | G14: 52 | H14: 28 | I14: 14 | J14: 0 | K14: 14 | L14: 14 | M14: 0 | N14: 0 | O14: 0 | P14: 10 | Q14: 14 | R14: 14 | S14: 14 | T14: 0 | U14: 0
A15: 542469500118D1 | B15: 118D1 | C15: 586688560-083 | D15: 0 | E15: 10 | F15: 0 | G15: 0 | H15: 0 | I15: 0 | J15: 0 | K15: 0 | L15: 0 | M15: 0 | N15: 0 | O15: 0 | P15: 0 | Q15: 0 | R15: 0 | S15: 0 | T15: 0 | U15: 0
A16: 542469500119D1 | B16: 119D1 | C16: 586688570-083 | D16: 265 | E16: 20 | F16: 280 | G16: 276 | H16: 42 | I16: 56 | J16: 70 | K16: 70 | L16: 42 | M16: 0 | N16: 0 | O16: 42 | P16: 42 | Q16: 52 | R16: 42 | S16: 56 | T16: 42 | U16: 0
A17: 542469500120D1 | B17: 120D1 | C17: 586450180-083 | D17: 15 | E17: 22 | F17: 14 | G17: 14 | H17: 0 | I17: 0 | J17: 0 | K17: 0 | L17: 14 | M17: 0 | N17: 0 | O17: 0 | P17: 0 | Q17: 0 | R17: 14 | S17: 0 | T17: 0 | U17: 0
A18: 546769500115D1 | B18: 115D1 | C18: 586688580-083 | D18: 0 | E18: 0 | F18: 0 | G18: 0 | H18: 0 | I18: 0 | J18: 0 | K18: 0 | L18: 0 | M18: 0 | N18: 0 | O18: 0 | P18: 0 | Q18: 0 | R18: 0 | S18: 0 | T18: 0 | U18: 0
A19: 546769500133D1 | B19: 133D1 | C19: 586688590-083 | D19: 10 | E19: 15 | F19: 14 | G19: 42 | H19: 0 | I19: 0 | J19: 0 | K19: 0 | L19: 14 | M19: 0 | N19: 0 | O19: 0 | P19: 0 | Q19: 0 | R19: 42 | S19: 0 | T19: 0 | U19: 0
A20: 546769500134D1 | B20: 134D1 | C20: 586688600-083 | D20: 33 | E20: 22 | F20: 42 | G20: 28 | H20: 0 | I20: 14 | J20: 14 | K20: 0 | L20: 14 | M20: 0 | N20: 0 | O20: 0 | P20: 0 | Q20: 0 | R20: 14 | S20: 0 | T20: 14 | U20: 0
A21: 546769500135D1 | B21: 135D1 | C21: 586688610-083 | D21: 7 | E21: 22 | F21: 14 | G21: 14 | H21: 14 | I21: 0 | J21: 0 | K21: 0 | L21: 0 | M21: 0 | N21: 0 | O21: 14 | P21: 0 | Q21: 0 | R21: 0 | S21: 0 | T21: 0 | U21: 0
A22: Customer Part No. | B22: Description | C22: Material Code | D22: Customer's Todays Plan | E22: CE open STK | F22: Total Plan | G22: Total Actual | H22: Vehicle Trip Plan | O22: Actual Dispatch
H23: T-1 | I23: T-2 | J23: T-3 | K23: T-4 | L23: T-5 | M23: T-6 | N23: T-7 | O23: T-1 | P23: T-2 | Q23: T-3 | R23: T-4 | S23: T-5 | T23: T-6 | U23: T-7
A25: 546469500102ZX | B25: 102ZX | C25: 587136190-083 | D25: 172 | E25: 12 | H25: 68 | I25: 48 | J25: 48 | K25: 64 | L25: 0 | M25: 0 | N25: 0 | O25: 68 | P25: 32 | Q25: 52 | R25: 48 | S25: 0 | T25: 0 | U25: 0 | W25: 200
A26: 546469500109ZY | B26: 109ZY | C26: 587136180-083 | D26: 37 | E26: 46 | F26: 32 | G26: 12 | H26: 0 | I26: 16 | J26: 16 | K26: 0 | L26: 0 | M26: 0 | O26: 0 | P26: 0 | Q26: 12 | R26: 0 | S26: 0 | T26: 0 | U26: 0 | W26: 12
A27: 546469500114ZY | B27: 114ZY | C27: 587011990-083 | D27: 84 | E27: 146 | F27: 32 | G27: 48 | H27: 0 | I27: 16 | J27: 16 | K27: 0 | L27: 0 | M27: 0 | O27: 0 | P27: 16 | Q27: 0 | R27: 32 | S27: 0 | T27: 0 | U27: 0 | W27: 48
A28: 546469500114ZZ | B28: 114ZZ | C28: 587011990-220 | D28: 44 | E28: 51 | F28: 16 | G28: 24 | H28: 0 | I28: 0 | J28: 0 | K28: 16 | L28: 0 | M28: 0 | O28: 0 | P28: 24 | Q28: 0 | R28: 0 | S28: 0 | T28: 0 | U28: 0 | W28: 24
A29: 546469500102ZZ | B29: 102ZZ | C29: 587136190-220 | D29: 22 | E29: 29 | F29: 32 | G29: 16 | H29: 0 | I29: 16 | J29: 16 | K29: 0 | L29: 0 | M29: 0 | O29: 0 | P29: 0 | Q29: 0 | R29: 16 | S29: 0 | T29: 0 | U29: 0 | W29: 16

Sheet 3-Sep (2)
F1: 45903 | M1: Vehicle Trip Plan | T1: Actual Dispatch | AE1: GAP
M2: T-1 | N2: T-2 | O2: T-3 | P2: T-4 | Q2: T-5 | R2: T-6 | T2: T-1 | U2: T-2 | V2: T-3 | W2: T-4 | X2: T-5 | Y2: T-6 | Z2: T-7 | AA2: T-8 | AB2: T=9 | AD2: Vehicle No. | AE2: T-1 | AF2: T-2 | AG2: T-3 | AH2: T-4 | AI2: T-5 | AJ2: T-6
A3: Customer Part No. | B3: Description | C3: Material Code | D3: Stocking Norm | E3: Customer's Todays Plan | F3: Stock at Customer End | G3: Stock on Wheel | H3: Dispatch Requirement | I3: Short against Requirement | J3: Total Plan | K3: Total Actual | L3: No Of Trolley | M3: 6 | N3: 6 | O3: 6 | P3: 6 | Q3: 6 | R3: 6 | S3: 36 | T3: 6 | U3: 3 | V3: 5 | W3: 4 | X3: 5 | Y3: 5 | AC3: 28 | AE3: 0 | AF3: -3 | AG3: -4 | AH3: 4 | AI3: -2 | AJ3: -8
L4: Vehicle No | AD4: Out Time
AD5: In time
L6: Time | M6: 0.27083333 | N6: 0.375 | O6: 0.5 | P6: 0.64583333 | Q6: 0.75 | T6: 0.27083333 | U6: 0.42083333 | V6: 0.49583333 | W6: 0.70138889 | X6: 0.80555556 | Y6: 0.90277778 | AD6: Actual | AE6: 0.27083333 | AF6: 0.29166667 | AG6: 0.40625 | AH6: 0.46875 | AI6: 0.61458333
A7: 542468900289ZZ | B7: Cluster GB | C7: 753000360-200 | D7: 184 | E7: 13 | F7: 108 | H7: 89 | I7: 89 | J7: 0 | K7: 0 | AD7: 0 | AE7: 0 | AF7: 0 | AG7: 0 | AH7: 0 | AI7: 0 | AJ7: 0
A8: 542468900289ZV | B8: Cluster ULS | C8: 753000360-324 | D8: 199 | E8: 299 | F8: 124 | H8: 374 | I8: 0 | J8: 576 | K8: 273 | N8: 96 | O8: 192 | P8: 192 | Q8: 96 | U8: 61 | V8: 20 | W8: 96 | X8: 96 | AD8: 273 | AE8: 0 | AF8: -35 | AG8: -207 | AH8: -207 | AI8: -303 | AJ8: -303
A9: 542468900289ZQ | B9: Cluster Titan Brown | C9: 753000360-011 | D9: 168 | E9: 28 | F9: 58 | H9: 138 | I9: 42 | J9: 96 | K9: 96 | N9: 96 | U9: 96 | AD9: 96 | AE9: 0 | AF9: 0 | AG9: 0 | AH9: 0 | AI9: 0 | AJ9: 0
A10: 542468910103CC | B10: Console LLG | C10: 753000370-009 | D10: 200 | E10: 4 | F10: 230 | H10: 0 | I10: 0 | J10: 0 | K10: 0 | AD10: 0 | AE10: 0 | AF10: 0 | AG10: 0 | AH10: 0 | AI10: 0 | AJ10: 0
A11: 542468910103D1 | B11: Console KLG | C11: 753000370-452 | D11: 260 | E11: 233 | F11: 260 | H11: 233 | I11: 233 | J11: 0 | K11: 260 | X11: 260 | AD11: 260 | AE11: 0 | AF11: 0 | AG11: 0 | AH11: 260 | AI11: 260 | AJ11: 260
A12: 542569500104D1 | B12: HMSL KLG | C12: 630131090-452 | D12: 140 | E12: 0 | F12: 200 | H12: 0 | I12: 0 | J12: 0 | K12: 0 | AD12: 0 | AE12: 0 | AF12: 0 | AG12: 0 | AH12: 0 | AI12: 0 | AJ12: 0
A13: 542569500104CC | B13: HMSL LLG | C13: 630131090 | D13: 140 | E13: 28 | F13: 140 | H13: 28 | I13: 28 | J13: 0 | K13: 0 | AD13: 0 | AE13: 0 | AF13: 0 | AG13: 0 | AH13: 0 | AI13: 0 | AJ13: 0
A14: 542469500102D1 | B14: 102D1 | C14: 586118320-083 | D14: 42 | E14: 82 | F14: 50 | H14: 74 | I14: 4 | J14: 70 | K14: 52 | M14: 28 | N14: 14 | P14: 14 | Q14: 14 | U14: 10 | V14: 14 | W14: 14 | X14: 14 | AD14: 52 | AE14: -28 | AF14: -32 | AG14: -18 | AH14: -4 | AI14: -18 | AJ14: -18
A15: 542469500118D1 | B15: 118D1 | C15: 586688560-083 | D15: 28 | E15: 0 | F15: 42 | H15: 0 | I15: 0 | J15: 0 | K15: 0 | AD15: 0 | AE15: 0 | AF15: 0 | AG15: 0 | AH15: 0 | AI15: 0 | AJ15: 0
A16: 542469500119D1 | B16: 119D1 | C16: 586688570-083 | D16: 84 | E16: 265 | F16: 70 | H16: 279 | I16: 0 | J16: 280 | K16: 276 | M16: 42 | N16: 56 | O16: 70 | P16: 70 | Q16: 42 | T16: 42 | U16: 42 | V16: 52 | W16: 42 | X16: 56 | Y16: 42 | AD16: 276 | AE16: 0 | AF16: -14 | AG16: -32 | AH16: 38 | AI16: -4 | AJ16: -4
A17: 542469500120D1 | B17: 120D1 | C17: 586450180-083 | D17: 28 | E17: 15 | F17: 30 | H17: 13 | I17: 0 | J17: 14 | K17: 14 | Q17: 14 | W17: 14 | AD17: 14 | AE17: 0 | AF17: 0 | AG17: 0 | AH17: 14 | AI17: 0 | AJ17: 0
A18: 546769500115D1 | B18: 115D1 | C18: 586688580-083 | D18: 0 | E18: 0 | F18: 0 | H18: 0 | I18: 0 | J18: 0 | K18: 0 | AD18: 0 | AE18: 0 | AF18: 0 | AG18: 0 | AH18: 0 | AI18: 0 | AJ18: 0
A19: 546769500133D1 | B19: 133D1 | C19: 586688590-083 | D19: 28 | E19: 10 | F19: 22 | H19: 16 | I19: 2 | J19: 14 | K19: 42 | Q19: 14 | W19: 42 | AD19: 42 | AE19: 0 | AF19: 0 | AG19: 0 | AH19: 42 | AI19: 28 | AJ19: 28
A20: 546769500134D1 | B20: 134D1 | C20: 586688600-083 | D20: 28 | E20: 33 | F20: 46 | H20: 15 | I20: 0 | J20: 42 | K20: 28 | N20: 14 | O20: 14 | Q20: 14 | W20: 14 | Y20: 14 | AD20: 28 | AE20: 0 | AF20: -14 | AG20: -28 | AH20: 0 | AI20: -14 | AJ20: -14
A21: 546769500135D1 | B21: 135D1 | C21: 586688610-083 | D21: 28 | E21: 7 | F21: 27 | H21: 8 | I21: 0 | J21: 14 | K21: 14 | M21: 14 | T21: 14 | AD21: 14 | AE21: 0 | AF21: 0 | AG21: 0 | AH21: 0 | AI21: 0 | AJ21: 0
A22: 542474700122 | B22: TAIL GATE | C22: 631161170-220 | D22: 50 | E22: 0 | F22: 55 | H22: 0 | I22: 0 | J22: 0 | K22: 0 | AD22: 0 | AE22: 0 | AF22: 0 | AG22: 0 | AH22: 0 | AI22: 0 | AJ22: 0
A23: 542463700115 | B23: SIDE RH | C23: 631161221-220 | D23: 50 | E23: 0 | F23: 60 | H23: 0 | I23: 0 | J23: 0 | K23: 0 | AD23: 0 | AE23: 0 | AF23: 0 | AG23: 0 | AH23: 0 | AI23: 0 | AJ23: 0
A24: 542463700114 | B24: SIDE LH | C24: 631161222-220 | D24: 50 | E24: 0 | F24: 42 | H24: 8 | I24: 8 | J24: 0 | K24: 0 | AD24: 0 | AE24: 0 | AF24: 0 | AG24: 0 | AH24: 0 | AI24: 0 | AJ24: 0
A25: 542472700140 | B25: FR RUBRAIL RH | C25: 631161181-220 | D25: 50 | E25: 0 | F25: 60 | H25: 0 | I25: 0 | J25: 0 | K25: 0 | AD25: 0 | AE25: 0 | AF25: 0 | AG25: 0 | AH25: 0 | AI25: 0 | AJ25: 0
A26: 542472700139 | B26: FR RUBRAIL LH | C26: 631161182-220 | D26: 50 | E26: 0 | F26: 40 | H26: 10 | I26: 10 | J26: 0 | K26: 0 | AD26: 0 | AE26: 0 | AF26: 0 | AG26: 0 | AH26: 0 | AI26: 0 | AJ26: 0
A27: 542473700124 | B27: RR RUBRAIL RH | C27: 631161191-220 | D27: 50 | E27: 0 | F27: 35 | H27: 15 | I27: 15 | J27: 0 | K27: 0 | AD27: 0 | AE27: 0 | AF27: 0 | AG27: 0 | AH27: 0 | AI27: 0 | AJ27: 0
A28: 542473700123 | B28: RR RUBRAIL LH | C28: 631161192-220 | D28: 50 | E28: 0 | F28: 36 | H28: 14 | I28: 14 | J28: 0 | K28: 0 | AD28: 0 | AE28: 0 | AF28: 0 | AG28: 0 | AH28: 0 | AI28: 0 | AJ28: 0
A29: 542488100121 | B29: FR WHEEL ARCH RH | C29: 631161201-220 | D29: 50 | E29: 0 | F29: 250 | H29: 0 | I29: 0 | J29: 0 | K29: 0 | AD29: 0 | AE29: 0 | AF29: 0 | AG29: 0 | AH29: 0 | AI29: 0 | AJ29: 0
A30: 542488100120 | B30: FR WHEEL ARCH LH | C30: 631161202-220 | D30: 50 | E30: 0 | F30: 50 | H30: 0 | I30: 0 | J30: 0 | K30: 0 | AD30: 0 | AE30: 0 | AF30: 0 | AG30: 0 | AH30: 0 | AI30: 0 | AJ30: 0
A31: 542488100123 | B31: RR WHEEL ARCH RH | C31: 631161211-220 | D31: 50 | E31: 0 | F31: 70 | H31: 0 | I31: 0 | J31: 0 | K31: 0 | AD31: 0 | AE31: 0 | AF31: 0 | AG31: 0 | AH31: 0 | AI31: 0 | AJ31: 0
A32: 542488100122 | B32: RR WHEEL ARCH LH | C32: 631161212-220 | D32: 50 | E32: 0 | F32: 30 | H32: 20 | I32: 20 | J32: 0 | K32: 0 | AD32: 0 | AE32: 0 | AF32: 0 | AG32: 0 | AH32: 0 | AI32: 0 | AJ32: 0
A33: 542490600102 | B33: ROOF RAIL RH | C33: 631122171-010 | D33: 50 | E33: 0 | F33: 40 | H33: 10 | I33: 10 | J33: 0 | K33: 0 | AD33: 0 | AE33: 0 | AF33: 0 | AG33: 0 | AH33: 0 | AI33: 0 | AJ33: 0
A34: 542490600101 | B34: ROOF RAIL LH | C34: 631122172-010 | D34: 50 | E34: 0 | F34: 40 | H34: 10 | I34: 10 | J34: 0 | K34: 0 | AD34: 0 | AE34: 0 | AF34: 0 | AG34: 0 | AH34: 0 | AI34: 0 | AJ34: 0
J35: 0 | K35: 1.8625 | T35: 0.27083333 | U35: 0.39791667 | V35: 0.52013889 | W35: 0.67361111 | AD35: Actual | AE35: 0.27083333
A36: 546469500102ZX | B36: 102ZX | C36: 587136190-083 | D36: 80 | E36: 172 | F36: 28 | H36: 224 | I36: 0 | J36: 228 | K36: 200 | M36: 68 | N36: 48 | O36: 48 | P36: 64 | T36: 68 | U36: 32 | V36: 52 | W36: 48 | AD36: 200 | AE36: 0 | AF36: -16 | AG36: -12 | AH36: -28 | AI36: -28 | AJ36: -28
A37: 546469500109ZY | B37: 109ZY | C37: 587136180-083 | D37: 32 | E37: 37 | F37: 35 | H37: 34 | I37: 2 | J37: 32 | K37: 12 | N37: 16 | O37: 16 | V37: 12 | AD37: 12 | AE37: 0 | AF37: -16 | AG37: -20 | AH37: -20 | AI37: -20 | AJ37: -20
A38: 546469500114ZY | B38: 114ZY | C38: 587011990-083 | D38: 64 | E38: 84 | F38: 116 | H38: 32 | I38: 0 | J38: 32 | K38: 48 | N38: 16 | O38: 16 | U38: 16 | W38: 32 | AD38: 48 | AE38: 0 | AF38: 0 | AG38: -16 | AH38: 16 | AI38: 16 | AJ38: 16
A39: 546469500114ZZ | B39: 114ZZ | C39: 587011990-220 | D39: 32 | E39: 44 | F39: 80 | H39: 0 | I39: 0 | J39: 16 | K39: 24 | P39: 16 | U39: 24 | AD39: 24 | AE39: 0 | AF39: 24 | AG39: 24 | AH39: 8 | AI39: 8 | AJ39: 8
A40: 546469500102ZZ | B40: 102ZZ | C40: 587136190-220 | D40: 32 | E40: 22 | F40: 25 | H40: 29 | I40: 0 | J40: 32 | K40: 16 | L40: - | N40: 16 | O40: 16 | W40: 16 | AD40: 16 | AE40: 0 | AF40: -16 | AG40: -32 | AH40: -16 | AI40: -16 | AJ40: -16
...

Sheet 5-Sep (2)
F1: 45905 | M1: Vehicle Trip Plan | T1: Actual Dispatch | AE1: GAP
M2: T-1 | N2: T-2 | O2: T-3 | P2: T-4 | Q2: T-5 | R2: T-6 | T2: T-1 | U2: T-2 | V2: T-3 | W2: T-4 | X2: T-5 | Y2: T-6 | Z2: T-7 | AA2: T-8 | AB2: T=9 | AD2: Vehicle No. | AE2: T-1 | AF2: T-2 | AG2: T-3 | AH2: T-4 | AI2: T-5 | AJ2: T-6
A3: Customer Part No. | B3: Description | C3: Material Code | D3: Stocking Norm | E3: Customer's Todays Plan | F3: Stock at Customer End | G3: Stock on Wheel | H3: Dispatch Requirement | I3: Short against Requirement | J3: Total Plan | K3: Total Actual | L3: No Of Trolley | M3: 6 | N3: 6 | O3: 6 | P3: 6 | Q3: 6 | R3: 6 | S3: 36 | T3: 6 | U3: 3 | V3: 5 | W3: 4 | X3: 5 | Y3: 5 | AC3: 28 | AE3: 0 | AF3: -3 | AG3: -4 | AH3: 4 | AI3: -2 | AJ3: -8
L4: Vehicle No | AD4: Out Time
AD5: In time
L6: Time | M6: 0.27083333 | N6: 0.41666667 | O6: 0.54166667 | P6: 0.66666667 | Q6: 0.79166667 | T6: 0.27083333 | U6: 0.46597222 | V6: 0.66041667 | W6: 0.6875 | X6: 0.85416667 | AD6: Actual | AE6: 0.27083333 | AF6: 0.29166667 | AG6: 0.40625 | AH6: 0.46875 | AI6: 0.61458333
A7: 542468900289ZZ | B7: Cluster GB | C7: 753000360-200 | D7: 184 | E7: 58 | F7: 100 | H7: 142 | I7: 46 | J7: 96 | K7: 0 | M7: 96 | AD7: 0 | AE7: -96 | AF7: -96 | AG7: -96 | AH7: -96 | AI7: -96 | AJ7: -96
A8: 542468900289ZV | B8: Cluster ULS | C8: 753000360-324 | D8: 199 | E8: 272 | F8: 210 | H8: 261 | I8: 0 | J8: 384 | K8: 288 | N8: 192 | O8: 96 | P8: 96 | U8: 96 | V8: 96 | X8: 96 | AD8: 288 | AE8: 0 | AF8: -96 | AG8: -96 | AH8: -96 | AI8: -96 | AJ8: -96
A9: 542468900289ZQ | B9: Cluster Titan Brown | C9: 753000360-011 | D9: 168 | E9: 40 | F9: 130 | H9: 78 | I9: 0 | J9: 96 | K9: 0 | O9: 96 | AD9: 0 | AE9: 0 | AF9: 0 | AG9: -96 | AH9: -96 | AI9: -96 | AJ9: -96
A10: 542468910103CC | B10: Console LLG | C10: 753000370-009 | D10: 200 | E10: 15 | F10: 200 | H10: 15 | I10: 15 | J10: 0 | K10: 0 | AD10: 0 | AE10: 0 | AF10: 0 | AG10: 0 | AH10: 0 | AI10: 0 | AJ10: 0
A11: 542468910103D1 | B11: Console KLG | C11: 753000370-452 | D11: 260 | E11: 173 | F11: 180 | H11: 253 | I11: 0 | J11: 260 | K11: 260 | N11: 130 | P11: 130 | U11: 130 | X11: 130 | AD11: 260 | AE11: 0 | AF11: 0 | AG11: 0 | AH11: 0 | AI11: 0 | AJ11: 0
A12: 542569500104D1 | B12: HMSL KLG | C12: 630131090-452 | D12: 140 | E12: 40 | F12: 150 | H12: 30 | I12: 30 | J12: 0 | K12: 0 | AD12: 0 | AE12: 0 | AF12: 0 | AG12: 0 | AH12: 0 | AI12: 0 | AJ12: 0
A13: 542569500104CC | B13: HMSL LLG | C13: 630131090 | D13: 140 | E13: 40 | F13: 60 | H13: 120 | I13: 0 | J13: 140 | K13: 0 | O13: 140 | AD13: 0 | AE13: 0 | AF13: 0 | AG13: -140 | AH13: -140 | AI13: -140 | AJ13: -140
A14: 542469500102D1 | B14: 102D1 | C14: 586118320-083 | D14: 42 | E14: 50 | F14: 42 | H14: 50 | I14: 0 | J14: 56 | K14: 42 | M14: 14 | N14: 14 | O14: 14 | P14: 14 | U14: 14 | W14: 14 | X14: 14 | AD14: 42 | AE14: -14 | AF14: -14 | AG14: -28 | AH14: -14 | AI14: -14 | AJ14: -14
A15: 542469500118D1 | B15: 118D1 | C15: 586688560-083 | D15: 28 | E15: 0 | F15: 44 | H15: 0 | I15: 0 | J15: 0 | K15: 0 | AD15: 0 | AE15: 0 | AF15: 0 | AG15: 0 | AH15: 0 | AI15: 0 | AJ15: 0
A16: 542469500119D1 | B16: 119D1 | C16: 586688570-083 | D16: 84 | E16: 234 | F16: 81 | H16: 237 | I16: 0 | J16: 252 | K16: 252 | M16: 42 | N16: 56 | O16: 56 | P16: 56 | Q16: 42 | T16: 42 | U16: 56 | V16: 42 | W16: 56 | X16: 56 | AD16: 252 | AE16: 0 | AF16: 0 | AG16: -14 | AH16: 42 | AI16: 0 | AJ16: 0
A17: 542469500120D1 | B17: 120D1 | C17: 586450180-083 | D17: 28 | E17: 36 | F17: 40 | H17: 24 | I17: 0 | J17: 28 | K17: 28 | N17: 14 | P17: 14 | V17: 14 | X17: 14 | AD17: 28 | AE17: 0 | AF17: -14 | AG17: 0 | AH17: 0 | AI17: 0 | AJ17: 0
A18: 546769500115D1 | B18: 115D1 | C18: 586688580-083 | D18: 0 | E18: 0 | F18: 0 | H18: 0 | I18: 0 | J18: 0 | K18: 0 | AD18: 0 | AE18: 0 | AF18: 0 | AG18: 0 | AH18: 0 | AI18: 0 | AJ18: 0
A19: 546769500133D1 | B19: 133D1 | C19: 586688590-083 | D19: 28 | E19: 0 | F19: 11 | H19: 17 | I19: 3 | J19: 14 | K19: 0 | M19: 14 | AD19: 0 | AE19: -14 | AF19: -14 | AG19: -14 | AH19: -14 | AI19: -14 | AJ19: -14
A20: 546769500134D1 | B20: 134D1 | C20: 586688600-083 | D20: 28 | E20: 40 | F20: 32 | H20: 36 | I20: 0 | J20: 42 | K20: 28 | M20: 14 | O20: 14 | Q20: 14 | V20: 28 | AD20: 28 | AE20: -14 | AF20: -14 | AG20: 0 | AH20: 0 | AI20: -14 | AJ20: -14
A21: 546769500135D1 | B21: 135D1 | C21: 586688610-083 | D21: 28 | E21: 0 | F21: 20 | H21: 8 | I21: 0 | J21: 14 | K21: 0 | Q21: 14 | AD21: 0 | AE21: 0 | AF21: 0 | AG21: 0 | AH21: 0 | AI21: -14 | AJ21: -14
A22: 542474700122 | B22: TAIL GATE | C22: 631161170-220 | D22: 50 | E22: 0 | F22: 55 | H22: 0 | I22: 0 | J22: 0 | K22: 0 | AD22: 0 | AE22: 0 | AF22: 0 | AG22: 0 | AH22: 0 | AI22: 0 | AJ22: 0
A23: 542463700115 | B23: SIDE RH | C23: 631161221-220 | D23: 50 | E23: 0 | F23: 60 | H23: 0 | I23: 0 | J23: 0 | K23: 0 | AD23: 0 | AE23: 0 | AF23: 0 | AG23: 0 | AH23: 0 | AI23: 0 | AJ23: 0
A24: 542463700114 | B24: SIDE LH | C24: 631161222-220 | D24: 50 | E24: 0 | F24: 42 | H24: 8 | I24: 8 | J24: 0 | K24: 0 | AD24: 0 | AE24: 0 | AF24: 0 | AG24: 0 | AH24: 0 | AI24: 0 | AJ24: 0
A25: 542472700140 | B25: FR RUBRAIL RH | C25: 631161181-220 | D25: 50 | E25: 0 | F25: 60 | H25: 0 | I25: 0 | J25: 0 | K25: 0 | AD25: 0 | AE25: 0 | AF25: 0 | AG25: 0 | AH25: 0 | AI25: 0 | AJ25: 0
A26: 542472700139 | B26: FR RUBRAIL LH | C26: 631161182-220 | D26: 50 | E26: 0 | F26: 40 | H26: 10 | I26: 10 | J26: 0 | K26: 0 | AD26: 0 | AE26: 0 | AF26: 0 | AG26: 0 | AH26: 0 | AI26: 0 | AJ26: 0
A27: 542473700124 | B27: RR RUBRAIL RH | C27: 631161191-220 | D27: 50 | E27: 0 | F27: 35 | H27: 15 | I27: 15 | J27: 0 | K27: 0 | AD27: 0 | AE27: 0 | AF27: 0 | AG27: 0 | AH27: 0 | AI27: 0 | AJ27: 0
A28: 542473700123 | B28: RR RUBRAIL LH | C28: 631161192-220 | D28: 50 | E28: 0 | F28: 36 | H28: 14 | I28: 14 | J28: 0 | K28: 0 | AD28: 0 | AE28: 0 | AF28: 0 | AG28: 0 | AH28: 0 | AI28: 0 | AJ28: 0
A29: 542488100121 | B29: FR WHEEL ARCH RH | C29: 631161201-220 | D29: 50 | E29: 0 | F29: 250 | H29: 0 | I29: 0 | J29: 0 | K29: 0 | AD29: 0 | AE29: 0 | AF29: 0 | AG29: 0 | AH29: 0 | AI29: 0 | AJ29: 0
A30: 542488100120 | B30: FR WHEEL ARCH LH | C30: 631161202-220 | D30: 50 | E30: 0 | F30: 50 | H30: 0 | I30: 0 | J30: 0 | K30: 0 | AD30: 0 | AE30: 0 | AF30: 0 | AG30: 0 | AH30: 0 | AI30: 0 | AJ30: 0
A31: 542488100123 | B31: RR WHEEL ARCH RH | C31: 631161211-220 | D31: 50 | E31: 0 | F31: 70 | H31: 0 | I31: 0 | J31: 0 | K31: 0 | AD31: 0 | AE31: 0 | AF31: 0 | AG31: 0 | AH31: 0 | AI31: 0 | AJ31: 0
A32: 542488100122 | B32: RR WHEEL ARCH LH | C32: 631161212-220 | D32: 50 | E32: 0 | F32: 30 | H32: 20 | I32: 20 | J32: 0 | K32: 0 | AD32: 0 | AE32: 0 | AF32: 0 | AG32: 0 | AH32: 0 | AI32: 0 | AJ32: 0
A33: 542490600102 | B33: ROOF RAIL RH | C33: 631122171-010 | D33: 50 | E33: 0 | F33: 40 | H33: 10 | I33: 10 | J33: 0 | K33: 0 | AD33: 0 | AE33: 0 | AF33: 0 | AG33: 0 | AH33: 0 | AI33: 0 | AJ33: 0
A34: 542490600101 | B34: ROOF RAIL LH | C34: 631122172-010 | D34: 50 | E34: 0 | F34: 40 | H34: 10 | I34: 10 | J34: 0 | K34: 0 | AD34: 0 | AE34: 0 | AF34: 0 | AG34: 0 | AH34: 0 | AI34: 0 | AJ34: 0
M35: 0.27083333 | N35: 0.375 | O35: 0.45833333 | P35: 0.54166667 | Q35: 0.625 | T35: 0.27083333 | U35: 0.42569444 | V35: 0.54861111 | AD35: Actual | AE35: 0.27083333
A36: 546469500102ZX | B36: 102ZX | C36: 587136190-083 | D36: 80 | E36: 124 | F36: 48 | H36: 156 | I36: 0 | J36: 160 | K36: 128 | M36: 48 | N36: 32 | O36: 32 | P36: 32 | Q36: 16 | T36: 44 | U36: 40 | V36: 44 | AD36: 128 | AE36: -4 | AF36: 4 | AG36: 16 | AH36: -16 | AI36: -32 | AJ36: -32
A37: 546469500109ZY | B37: 109ZY | C37: 587136180-083 | D37: 32 | E37: 22 | F37: 17 | H37: 37 | I37: 0 | J37: 48 | K37: 16 | M37: 16 | O37: 16 | Q37: 16 | T37: 16 | AD37: 16 | AE37: 0 | AF37: 0 | AG37: -16 | AH37: -16 | AI37: -32 | AJ37: -32
A38: 546469500114ZY | B38: 114ZY | C38: 587011990-083 | D38: 64 | E38: 212 | F38: 130 | H38: 146 | I38: 2 | J38: 144 | K38: 60 | N38: 32 | O38: 32 | P38: 48 | Q38: 32 | U38: 12 | V38: 48 | AD38: 60 | AE38: 0 | AF38: -20 | AG38: -4 | AH38: -52 | AI38: -84 | AJ38: -84
A39: 546469500114ZZ | B39: 114ZZ | C39: 587011990-220 | D39: 32 | E39: 114 | F39: 92 | H39: 54 | I39: 0 | J39: 64 | K39: 32 | M39: 16 | N39: 16 | O39: 16 | P39: 16 | T39: 16 | U39: 16 | AD39: 32 | AE39: 0 | AF39: 0 | AG39: -16 | AH39: -32 | AI39: -32 | AJ39: -32
A40: 546469500102ZZ | B40: 102ZZ | C40: 587136190-220 | D40: 32 | E40: 34 | F40: 40 | H40: 26 | I40: 0 | J40: 32 | K40: 0 | L40: - | M40: 16 | N40: 16 | AD40: 0 | AE40: -16 | AF40: -32 | AG40: -32 | AH40: -32 | AI40: -32 | AJ40: -32
...

Sheet 05092025 (2)
C1: 45905 | H1: Vehicle Trip Plan | O1: Actual Dispatch
H2: T-1 | I2: T-2 | J2: T-3 | K2: T-4 | L2: T-5 | M2: T-6 | N2: T-7 | O2: T-1 | P2: T-2 | Q2: T-3 | R2: T-4 | S2: T-5 | T2: T-6 | U2: T-7 | V2: T-8
A3: Customer Part No. | B3: Description | C3: Material Code | D3: Customer's Todays Plan | E3: Vehicle No | F3: Total Plan | G3: Total Actual | H3: 0 | I3: 0 | J3: 0 | K3: 0 | L3: 0 | M3: 0 | N3: 0 | O3: 0 | P3: 0 | Q3: 0 | R3: 0 | S3: 0 | T3: 0 | U3: 0
E4: Intime
E5: Out Time
E6: CE open STK | H6: 0.27083333 | I6: 0.41666667 | J6: 0.54166667 | K6: 0.66666667 | L6: 0.79166667 | M6: 0 | O6: 0.27083333 | P6: 0.46597222 | Q6: 0.66041667 | R6: 0.6875 | S6: 0.85416667 | T6: 0 | U6: 0
A7: 542468900289ZZ | B7: Cluster GB | C7: 753000360-200 | D7: 58 | E7: 100 | F7: 96 | G7: 0 | H7: 96 | I7: 0 | J7: 0 | K7: 0 | L7: 0 | M7: 0 | N7: 0 | O7: 0 | P7: 0 | Q7: 0 | R7: 0 | S7: 0 | T7: 0 | U7: 0
A8: 542468900289ZV | B8: Cluster ULS | C8: 753000360-324 | D8: 272 | E8: 192 | F8: 384 | G8: 288 | H8: 0 | I8: 192 | J8: 96 | K8: 96 | L8: 0 | M8: 0 | N8: 0 | O8: 0 | P8: 96 | Q8: 96 | R8: 0 | S8: 96 | T8: 0 | U8: 0
A9: 542468900289ZQ | B9: Cluster Titan Brown | C9: 753000360-011 | D9: 40 | E9: 40 | F9: 96 | G9: 0 | H9: 0 | I9: 0 | J9: 96 | K9: 0 | L9: 0 | M9: 0 | N9: 0 | O9: 0 | P9: 0 | Q9: 0 | R9: 0 | S9: 0 | T9: 0 | U9: 0
A10: 542468910103CC | B10: Console LLG | C10: 753000370-009 | D10: 15 | E10: 240 | F10: 0 | G10: 0 | H10: 0 | I10: 0 | J10: 0 | K10: 0 | L10: 0 | M10: 0 | N10: 0 | O10: 0 | P10: 0 | Q10: 0 | R10: 0 | S10: 0 | T10: 0 | U10: 0
A11: 542468910103D1 | B11: Console KLG | C11: 753000370-452 | D11: 173 | E11: 130 | F11: 260 | G11: 260 | H11: 0 | I11: 130 | J11: 0 | K11: 130 | L11: 0 | M11: 0 | N11: 0 | O11: 0 | P11: 130 | Q11: 0 | R11: 0 | S11: 130 | T11: 0 | U11: 0
A12: 542569500104D1 | B12: HMSL KLG | C12: 630131090-452 | D12: 40 | E12: 200 | F12: 0 | G12: 0 | H12: 0 | I12: 0 | J12: 0 | K12: 0 | L12: 0 | M12: 0 | N12: 0 | O12: 0 | P12: 0 | Q12: 0 | R12: 0 | S12: 0 | T12: 0 | U12: 0
A13: 542569500104CC | B13: HMSL LLG | C13: 630131090 | D13: 40 | E13: 40 | F13: 140 | G13: 0 | H13: 0 | I13: 0 | J13: 140 | K13: 0 | L13: 0 | M13: 0 | N13: 0 | O13: 0 | P13: 0 | Q13: 0 | R13: 0 | S13: 0 | T13: 0 | U13: 0
A14: 542469500102D1 | B14: 102D1 | C14: 586118320-083 | D14: 50 | E14: 45 | F14: 56 | G14: 42 | H14: 14 | I14: 14 | J14: 14 | K14: 14 | L14: 0 | M14: 0 | N14: 0 | O14: 0 | P14: 14 | Q14: 0 | R14: 14 | S14: 14 | T14: 0 | U14: 0
A15: 542469500118D1 | B15: 118D1 | C15: 586688560-083 | D15: 0 | E15: 10 | F15: 0 | G15: 0 | H15: 0 | I15: 0 | J15: 0 | K15: 0 | L15: 0 | M15: 0 | N15: 0 | O15: 0 | P15: 0 | Q15: 0 | R15: 0 | S15: 0 | T15: 0 | U15: 0
A16: 542469500119D1 | B16: 119D1 | C16: 586688570-083 | D16: 234 | E16: 20 | F16: 252 | G16: 252 | H16: 42 | I16: 56 | J16: 56 | K16: 56 | L16: 42 | M16: 0 | N16: 0 | O16: 42 | P16: 56 | Q16: 42 | R16: 56 | S16: 56 | T16: 0 | U16: 0
A17: 542469500120D1 | B17: 120D1 | C17: 586450180-083 | D17: 36 | E17: 22 | F17: 28 | G17: 28 | H17: 0 | I17: 14 | J17: 0 | K17: 14 | L17: 0 | M17: 0 | N17: 0 | O17: 0 | P17: 0 | Q17: 14 | R17: 0 | S17: 14 | T17: 0 | U17: 0
A18: 546769500115D1 | B18: 115D1 | C18: 586688580-083 | D18: 0 | E18: 0 | F18: 0 | G18: 0 | H18: 0 | I18: 0 | J18: 0 | K18: 0 | L18: 0 | M18: 0 | N18: 0 | O18: 0 | P18: 0 | Q18: 0 | R18: 0 | S18: 0 | T18: 0 | U18: 0
A19: 546769500133D1 | B19: 133D1 | C19: 586688590-083 | D19: 0 | E19: 15 | F19: 14 | G19: 0 | H19: 14 | I19: 0 | J19: 0 | K19: 0 | L19: 0 | M19: 0 | N19: 0 | O19: 0 | P19: 0 | Q19: 0 | R19: 0 | S19: 0 | T19: 0 | U19: 0
A20: 546769500134D1 | B20: 134D1 | C20: 586688600-083 | D20: 40 | E20: 22 | F20: 42 | G20: 28 | H20: 14 | I20: 0 | J20: 14 | K20: 0 | L20: 14 | M20: 0 | N20: 0 | O20: 0 | P20: 0 | Q20: 28 | R20: 0 | S20: 0 | T20: 0 | U20: 0
A21: 546769500135D1 | B21: 135D1 | C21: 586688610-083 | D21: 0 | E21: 22 | F21: 14 | G21: 0 | H21: 0 | I21: 0 | J21: 0 | K21: 0 | L21: 14 | M21: 0 | N21: 0 | O21: 0 | P21: 0 | Q21: 0 | R21: 0 | S21: 0 | T21: 0 | U21: 0
A22: Customer Part No. | B22: Description | C22: Material Code | D22: Customer's Todays Plan | E22: CE open STK | F22: Total Plan | G22: Total Actual | H22: Vehicle Trip Plan | O22: Actual Dispatch
H23: T-1 | I23: T-2 | J23: T-3 | K23: T-4 | L23: T-5 | M23: T-6 | N23: T-7 | O23: T-1 | P23: T-2 | Q23: T-3 | R23: T-4 | S23: T-5 | T23: T-6 | U23: T-7
H24: 0.27083333 | I24: 0.375 | J24: 0.45833333 | K24: 0.54166667 | L24: 0.625
A25: 546469500102ZX | B25: 102ZX | C25: 587136190-083 | D25: 124 | E25: 12 | H25: 48 | I25: 32 | J25: 32 | K25: 32 | L25: 16 | M25: 0 | N25: 0 | O25: 44 | P25: 40 | Q25: 44 | R25: 0 | S25: 0 | T25: 0 | U25: 0 | W25: 128
A26: 546469500109ZY | B26: 109ZY | C26: 587136180-083 | D26: 22 | E26: 46 | F26: 48 | G26: 16 | H26: 16 | I26: 0 | J26: 16 | K26: 0 | L26: 16 | M26: 0 | O26: 16 | P26: 0 | Q26: 0 | R26: 0 | S26: 0 | T26: 0 | U26: 0 | W26: 16
A27: 546469500114ZY | B27: 114ZY | C27: 587011990-083 | D27: 212 | E27: 146 | F27: 144 | G27: 60 | H27: 0 | I27: 32 | J27: 32 | K27: 48 | L27: 32 | M27: 0 | O27: 0 | P27: 12 | Q27: 48 | R27: 0 | S27: 0 | T27: 0 | U27: 0 | W27: 60
A28: 546469500114ZZ | B28: 114ZZ | C28: 587011990-220 | D28: 114 | E28: 51 | F28: 64 | G28: 32 | H28: 16 | I28: 16 | J28: 16 | K28: 16 | L28: 0 | M28: 0 | O28: 16 | P28: 16 | Q28: 0 | R28: 0 | S28: 0 | T28: 0 | U28: 0 | W28: 32
A29: 546469500102ZZ | B29: 102ZZ | C29: 587136190-220 | D29: 34 | E29: 29 | F29: 32 | G29: 0 | H29: 16 | I29: 16 | J29: 0 | K29: 0 | L29: 0 | M29: 0 | O29: 0 | P29: 0 | Q29: 0 | R29: 0 | S29: 0 | T29: 0 | U29: 0 | W29: 0

Sheet 4-Sep (2)
F1: 45904 | M1: Vehicle Trip Plan | T1: Actual Dispatch | AE1: GAP
M2: T-1 | N2: T-2 | O2: T-3 | P2: T-4 | Q2: T-5 | R2: T-6 | T2: T-1 | U2: T-2 | V2: T-3 | W2: T-4 | X2: T-5 | Y2: T-6 | Z2: T-7 | AA2: T-8 | AB2: T=9 | AD2: Vehicle No. | AE2: T-1 | AF2: T-2 | AG2: T-3 | AH2: T-4 | AI2: T-5 | AJ2: T-6
A3: Customer Part No. | B3: Description | C3: Material Code | D3: Stocking Norm | E3: Customer's Todays Plan | F3: Stock at Customer End | G3: Stock on Wheel | H3: Dispatch Requirement | I3: Short against Requirement | J3: Total Plan | K3: Total Actual | L3: No Of Trolley | M3: 6 | N3: 6 | O3: 6 | P3: 6 | Q3: 6 | R3: 6 | S3: 36 | T3: 6 | U3: 3 | V3: 5 | W3: 4 | X3: 5 | Y3: 5 | AC3: 28 | AE3: 0 | AF3: -3 | AG3: -4 | AH3: 4 | AI3: -2 | AJ3: -8
L4: Vehicle No | AD4: Out Time
AD5: In time
L6: Time | M6: 0.27083333 | N6: 0.41666667 | O6: 0.54166667 | P6: 0.66666667 | Q6: 0.79166667 | T6: 0.27083333 | U6: 0.45625 | V6: 0.52083333 | W6: 0.66666667 | X6: 0.79166667 | Y6: 0.89583333 | AD6: Actual | AE6: 0.27083333 | AF6: 0.29166667 | AG6: 0.40625 | AH6: 0.46875 | AI6: 0.61458333
A7: 542468900289ZZ | B7: Cluster GB | C7: 753000360-200 | D7: 184 | E7: 26 | F7: 100 | H7: 110 | I7: 14 | J7: 96 | K7: 0 | Q7: 96 | AD7: 0 | AE7: 0 | AF7: 0 | AG7: 0 | AH7: 0 | AI7: -96 | AJ7: -96
A8: 542468900289ZV | B8: Cluster ULS | C8: 753000360-324 | D8: 199 | E8: 276 | F8: 30 | H8: 445 | I8: 0 | J8: 480 | K8: 480 | M8: 96 | N8: 96 | O8: 96 | P8: 96 | Q8: 96 | T8: 96 | U8: 192 | W8: 192 | AD8: 480 | AE8: 0 | AF8: 96 | AG8: 0 | AH8: 96 | AI8: 0 | AJ8: 0
A9: 542468900289ZQ | B9: Cluster Titan Brown | C9: 753000360-011 | D9: 168 | E9: 24 | F9: 130 | H9: 62 | I9: 0 | J9: 96 | K9: 0 | P9: 96 | AD9: 0 | AE9: 0 | AF9: 0 | AG9: 0 | AH9: -96 | AI9: -96 | AJ9: -96
A10: 542468910103CC | B10: Console LLG | C10: 753000370-009 | D10: 200 | E10: 12 | F10: 218 | H10: 0 | I10: 0 | J10: 0 | K10: 0 | AD10: 0 | AE10: 0 | AF10: 0 | AG10: 0 | AH10: 0 | AI10: 0 | AJ10: 0
A11: 542468910103D1 | B11: Console KLG | C11: 753000370-452 | D11: 260 | E11: 188 | F11: 240 | H11: 208 | I11: 0 | J11: 260 | K11: 260 | O11: 130 | P11: 130 | U11: 130 | W11: 130 | AD11: 260 | AE11: 0 | AF11: 130 | AG11: 0 | AH11: 0 | AI11: 0 | AJ11: 0
A12: 542569500104D1 | B12: HMSL KLG | C12: 630131090-452 | D12: 140 | E12: 10 | F12: 190 | H12: 0 | I12: 0 | J12: 0 | K12: 0 | AD12: 0 | AE12: 0 | AF12: 0 | AG12: 0 | AH12: 0 | AI12: 0 | AJ12: 0
A13: 542569500104CC | B13: HMSL LLG | C13: 630131090 | D13: 140 | E13: 24 | F13: 100 | H13: 64 | I13: 0 | J13: 140 | K13: 0 | Q13: 140 | AD13: 0 | AE13: 0 | AF13: 0 | AG13: 0 | AH13: 0 | AI13: -140 | AJ13: -140
A14: 542469500102D1 | B14: 102D1 | C14: 586118320-083 | D14: 42 | E14: 25 | F14: 58 | H14: 9 | I14: 0 | J14: 14 | K14: 42 | M14: 14 | V14: 14 | W14: 14 | Y14: 14 | AD14: 42 | AE14: -14 | AF14: -14 | AG14: 0 | AH14: 28 | AI14: 28 | AJ14: 28
A15: 542469500118D1 | B15: 118D1 | C15: 586688560-083 | D15: 28 | E15: 0 | F15: 42 | H15: 0 | I15: 0 | J15: 0 | K15: 0 | AD15: 0 | AE15: 0 | AF15: 0 | AG15: 0 | AH15: 0 | AI15: 0 | AJ15: 0
A16: 542469500119D1 | B16: 119D1 | C16: 586688570-083 | D16: 84 | E16: 306 | F16: 80 | H16: 310 | I16: 2 | J16: 308 | K16: 294 | M16: 28 | N16: 70 | O16: 70 | P16: 84 | Q16: 56 | T16: 28 | U16: 56 | V16: 56 | W16: 56 | X16: 56 | Y16: 42 | AD16: 294 | AE16: 0 | AF16: -14 | AG16: -28 | AH16: 42 | AI16: -14 | AJ16: -14
A17: 542469500120D1 | B17: 120D1 | C17: 586450180-083 | D17: 28 | E17: 15 | F17: 28 | H17: 15 | I17: 0 | J17: 28 | K17: 28 | M17: 14 | Q17: 14 | W17: 14 | X17: 14 | AD17: 28 | AE17: -14 | AF17: -14 | AG17: -14 | AH17: 14 | AI17: 0 | AJ17: 0
A18: 546769500115D1 | B18: 115D1 | C18: 586688580-083 | D18: 0 | E18: 0 | F18: 0 | H18: 0 | I18: 0 | J18: 0 | K18: 0 | AD18: 0 | AE18: 0 | AF18: 0 | AG18: 0 | AH18: 0 | AI18: 0 | AJ18: 0
A19: 546769500133D1 | B19: 133D1 | C19: 586688590-083 | D19: 28 | E19: 0 | F19: 14 | H19: 14 | I19: 0 | J19: 14 | K19: 0 | Q19: 14 | AD19: 0 | AE19: 0 | AF19: 0 | AG19: 0 | AH19: 0 | AI19: -14 | AJ19: -14
A20: 546769500134D1 | B20: 134D1 | C20: 586688600-083 | D20: 28 | E20: 46 | F20: 40 | H20: 34 | I20: 0 | J20: 56 | K20: 14 | M20: 28 | N20: 14 | O20: 14 | T20: 14 | AD20: 14 | AE20: -14 | AF20: -28 | AG20: -42 | AH20: -42 | AI20: -42 | AJ20: -42
A21: 546769500135D1 | B21: 135D1 | C21: 586688610-083 | D21: 28 | E21: 12 | F21: 44 | H21: 0 | I21: 0 | J21: 0 | K21: 0 | AD21: 0 | AE21: 0 | AF21: 0 | AG21: 0 | AH21: 0 | AI21: 0 | AJ21: 0
A22: 542474700122 | B22: TAIL GATE | C22: 631161170-220 | D22: 50 | E22: 0 | F22: 55 | H22: 0 | I22: 0 | J22: 0 | K22: 0 | AD22: 0 | AE22: 0 | AF22: 0 | AG22: 0 | AH22: 0 | AI22: 0 | AJ22: 0
A23: 542463700115 | B23: SIDE RH | C23: 631161221-220 | D23: 50 | E23: 0 | F23: 60 | H23: 0 | I23: 0 | J23: 0 | K23: 0 | AD23: 0 | AE23: 0 | AF23: 0 | AG23: 0 | AH23: 0 | AI23: 0 | AJ23: 0
A24: 542463700114 | B24: SIDE LH | C24: 631161222-220 | D24: 50 | E24: 0 | F24: 42 | H24: 8 | I24: 8 | J24: 0 | K24: 0 | AD24: 0 | AE24: 0 | AF24: 0 | AG24: 0 | AH24: 0 | AI24: 0 | AJ24: 0
A25: 542472700140 | B25: FR RUBRAIL RH | C25: 631161181-220 | D25: 50 | E25: 0 | F25: 60 | H25: 0 | I25: 0 | J25: 0 | K25: 0 | AD25: 0 | AE25: 0 | AF25: 0 | AG25: 0 | AH25: 0 | AI25: 0 | AJ25: 0
A26: 542472700139 | B26: FR RUBRAIL LH | C26: 631161182-220 | D26: 50 | E26: 0 | F26: 40 | H26: 10 | I26: 10 | J26: 0 | K26: 0 | AD26: 0 | AE26: 0 | AF26: 0 | AG26: 0 | AH26: 0 | AI26: 0 | AJ26: 0
A27: 542473700124 | B27: RR RUBRAIL RH | C27: 631161191-220 | D27: 50 | E27: 0 | F27: 35 | H27: 15 | I27: 15 | J27: 0 | K27: 0 | AD27: 0 | AE27: 0 | AF27: 0 | AG27: 0 | AH27: 0 | AI27: 0 | AJ27: 0
A28: 542473700123 | B28: RR RUBRAIL LH | C28: 631161192-220 | D28: 50 | E28: 0 | F28: 36 | H28: 14 | I28: 14 | J28: 0 | K28: 0 | AD28: 0 | AE28: 0 | AF28: 0 | AG28: 0 | AH28: 0 | AI28: 0 | AJ28: 0
A29: 542488100121 | B29: FR WHEEL ARCH RH | C29: 631161201-220 | D29: 50 | E29: 0 | F29: 250 | H29: 0 | I29: 0 | J29: 0 | K29: 0 | AD29: 0 | AE29: 0 | AF29: 0 | AG29: 0 | AH29: 0 | AI29: 0 | AJ29: 0
A30: 542488100120 | B30: FR WHEEL ARCH LH | C30: 631161202-220 | D30: 50 | E30: 0 | F30: 50 | H30: 0 | I30: 0 | J30: 0 | K30: 0 | AD30: 0 | AE30: 0 | AF30: 0 | AG30: 0 | AH30: 0 | AI30: 0 | AJ30: 0
A31: 542488100123 | B31: RR WHEEL ARCH RH | C31: 631161211-220 | D31: 50 | E31: 0 | F31: 70 | H31: 0 | I31: 0 | J31: 0 | K31: 0 | AD31: 0 | AE31: 0 | AF31: 0 | AG31: 0 | AH31: 0 | AI31: 0 | AJ31: 0
A32: 542488100122 | B32: RR WHEEL ARCH LH | C32: 631161212-220 | D32: 50 | E32: 0 | F32: 30 | H32: 20 | I32: 20 | J32: 0 | K32: 0 | AD32: 0 | AE32: 0 | AF32: 0 | AG32: 0 | AH32: 0 | AI32: 0 | AJ32: 0
A33: 542490600102 | B33: ROOF RAIL RH | C33: 631122171-010 | D33: 50 | E33: 0 | F33: 40 | H33: 10 | I33: 10 | J33: 0 | K33: 0 | AD33: 0 | AE33: 0 | AF33: 0 | AG33: 0 | AH33: 0 | AI33: 0 | AJ33: 0
A34: 542490600101 | B34: ROOF RAIL LH | C34: 631122172-010 | D34: 50 | E34: 0 | F34: 40 | H34: 10 | I34: 10 | J34: 0 | K34: 0 | AD34: 0 | AE34: 0 | AF34: 0 | AG34: 0 | AH34: 0 | AI34: 0 | AJ34: 0
M35: 0.27083333 | N35: 0.375 | O35: 0.45833333 | P35: 0.54166667 | Q35: 0.625 | T35: 0.27083333 | U35: 0.36944444 | V35: 0.58333333 | AD35: Actual | AE35: 0.27083333
A36: 546469500102ZX | B36: 102ZX | C36: 587136190-083 | D36: 80 | E36: 142 | F36: 70 | H36: 152 | I36: 8 | J36: 144 | K36: 60 | M36: 16 | N36: 32 | O36: 32 | P36: 32 | Q36: 32 | T36: 12 | U36: 0 | V36: 48 | AD36: 60 | AE36: -4 | AF36: -36 | AG36: -20 | AH36: -52 | AI36: -84 | AJ36: -84
A37: 546469500109ZY | B37: 109ZY | C37: 587136180-083 | D37: 32 | E37: 19 | F37: 27 | H37: 24 | I37: 0 | J37: 32 | K37: 0 | O37: 16 | P37: 16 | AD37: 0 | AE37: 0 | AF37: 0 | AG37: -16 | AH37: -32 | AI37: -32 | AJ37: -32
A38: 546469500114ZY | B38: 114ZY | C38: 587011990-083 | D38: 64 | E38: 208 | F38: 116 | H38: 156 | I38: 0 | J38: 160 | K38: 108 | M38: 48 | N38: 32 | O38: 16 | P38: 16 | Q38: 48 | T38: 48 | U38: 60 | AD38: 108 | AE38: 0 | AF38: 28 | AG38: 12 | AH38: -4 | AI38: -52 | AJ38: -52
A39: 546469500114ZZ | B39: 114ZZ | C39: 587011990-220 | D39: 32 | E39: 103 | F39: 76 | H39: 59 | I39: 0 | J39: 80 | K39: 44 | M39: 16 | N39: 16 | O39: 16 | P39: 16 | Q39: 16 | T39: 12 | V39: 32 | AD39: 44 | AE39: -4 | AF39: -20 | AG39: -4 | AH39: -20 | AI39: -36 | AJ39: -36
A40: 546469500102ZZ | B40: 102ZZ | C40: 587136190-220 | D40: 32 | E40: 48 | F40: 16 | H40: 64 | I40: 0 | J40: 64 | K40: 32 | L40: - | M40: 16 | N40: 16 | O40: 16 | P40: 16 | T40: 16 | V40: 16 | AD40: 32 | AE40: 0 | AF40: -16 | AG40: -16 | AH40: -32 | AI40: -32 | AJ40: -32
...

Sheet 04092025 (2)
C1: 45904 | H1: Vehicle Trip Plan | O1: Actual Dispatch
H2: T-1 | I2: T-2 | J2: T-3 | K2: T-4 | L2: T-5 | M2: T-6 | N2: T-7 | O2: T-1 | P2: T-2 | Q2: T-3 | R2: T-4 | S2: T-5 | T2: T-6 | U2: T-7 | V2: T-8
A3: Customer Part No. | B3: Description | C3: Material Code | D3: Customer's Todays Plan | E3: Vehicle No | F3: Total Plan | G3: Total Actual | H3: 0 | I3: 0 | J3: 0 | K3: 0 | L3: 0 | M3: 0 | N3: 0 | O3: 0 | P3: 0 | Q3: 0 | R3: 0 | S3: 0 | T3: 0 | U3: 0
E4: Intime
E5: Out Time
E6: CE open STK | H6: 0.27083333 | I6: 0.41666667 | J6: 0.54166667 | K6: 0.66666667 | L6: 0.79166667 | M6: 0 | O6: 0.27083333 | P6: 0.45625 | Q6: 0.52083333 | R6: 0.66666667 | S6: 0.79166667 | T6: 0.89583333 | U6: 0
A7: 542468900289ZZ | B7: Cluster GB | C7: 753000360-200 | D7: 26 | E7: 100 | F7: 96 | G7: 0 | H7: 0 | I7: 0 | J7: 0 | K7: 0 | L7: 96 | M7: 0 | N7: 0 | O7: 0 | P7: 0 | Q7: 0 | R7: 0 | S7: 0 | T7: 0 | U7: 0
A8: 542468900289ZV | B8: Cluster ULS | C8: 753000360-324 | D8: 276 | E8: 192 | F8: 480 | G8: 480 | H8: 96 | I8: 96 | J8: 96 | K8: 96 | L8: 96 | M8: 0 | N8: 0 | O8: 96 | P8: 192 | Q8: 0 | R8: 192 | S8: 0 | T8: 0 | U8: 0
A9: 542468900289ZQ | B9: Cluster Titan Brown | C9: 753000360-011 | D9: 24 | E9: 40 | F9: 96 | G9: 0 | H9: 0 | I9: 0 | J9: 0 | K9: 96 | L9: 0 | M9: 0 | N9: 0 | O9: 0 | P9: 0 | Q9: 0 | R9: 0 | S9: 0 | T9: 0 | U9: 0
A10: 542468910103CC | B10: Console LLG | C10: 753000370-009 | D10: 12 | E10: 240 | F10: 0 | G10: 0 | H10: 0 | I10: 0 | J10: 0 | K10: 0 | L10: 0 | M10: 0 | N10: 0 | O10: 0 | P10: 0 | Q10: 0 | R10: 0 | S10: 0 | T10: 0 | U10: 0
A11: 542468910103D1 | B11: Console KLG | C11: 753000370-452 | D11: 188 | E11: 130 | F11: 260 | G11: 260 | H11: 0 | I11: 0 | J11: 130 | K11: 130 | L11: 0 | M11: 0 | N11: 0 | O11: 0 | P11: 130 | Q11: 0 | R11: 130 | S11: 0 | T11: 0 | U11: 0
A12: 542569500104D1 | B12: HMSL KLG | C12: 630131090-452 | D12: 10 | E12: 200 | F12: 0 | G12: 0 | H12: 0 | I12: 0 | J12: 0 | K12: 0 | L12: 0 | M12: 0 | N12: 0 | O12: 0 | P12: 0 | Q12: 0 | R12: 0 | S12: 0 | T12: 0 | U12: 0
A13: 542569500104CC | B13: HMSL LLG | C13: 630131090 | D13: 24 | E13: 40 | F13: 140 | G13: 0 | H13: 0 | I13: 0 | J13: 0 | K13: 0 | L13: 140 | M13: 0 | N13: 0 | O13: 0 | P13: 0 | Q13: 0 | R13: 0 | S13: 0 | T13: 0 | U13: 0
A14: 542469500102D1 | B14: 102D1 | C14: 586118320-083 | D14: 25 | E14: 45 | F14: 14 | G14: 42 | H14: 14 | I14: 0 | J14: 0 | K14: 0 | L14: 0 | M14: 0 | N14: 0 | O14: 0 | P14: 0 | Q14: 14 | R14: 14 | S14: 0 | T14: 14 | U14: 0
A15: 542469500118D1 | B15: 118D1 | C15: 586688560-083 | D15: 0 | E15: 10 | F15: 0 | G15: 0 | H15: 0 | I15: 0 | J15: 0 | K15: 0 | L15: 0 | M15: 0 | N15: 0 | O15: 0 | P15: 0 | Q15: 0 | R15: 0 | S15: 0 | T15: 0 | U15: 0
A16: 542469500119D1 | B16: 119D1 | C16: 586688570-083 | D16: 306 | E16: 20 | F16: 308 | G16: 294 | H16: 28 | I16: 70 | J16: 70 | K16: 84 | L16: 56 | M16: 0 | N16: 0 | O16: 28 | P16: 56 | Q16: 56 | R16: 56 | S16: 56 | T16: 42 | U16: 0
A17: 542469500120D1 | B17: 120D1 | C17: 586450180-083 | D17: 15 | E17: 22 | F17: 28 | G17: 28 | H17: 14 | I17: 0 | J17: 0 | K17: 0 | L17: 14 | M17: 0 | N17: 0 | O17: 0 | P17: 0 | Q17: 0 | R17: 14 | S17: 14 | T17: 0 | U17: 0
A18: 546769500115D1 | B18: 115D1 | C18: 586688580-083 | D18: 0 | E18: 0 | F18: 0 | G18: 0 | H18: 0 | I18: 0 | J18: 0 | K18: 0 | L18: 0 | M18: 0 | N18: 0 | O18: 0 | P18: 0 | Q18: 0 | R18: 0 | S18: 0 | T18: 0 | U18: 0
A19: 546769500133D1 | B19: 133D1 | C19: 586688590-083 | D19: 0 | E19: 15 | F19: 14 | G19: 0 | H19: 0 | I19: 0 | J19: 0 | K19: 0 | L19: 14 | M19: 0 | N19: 0 | O19: 0 | P19: 0 | Q19: 0 | R19: 0 | S19: 0 | T19: 0 | U19: 0
A20: 546769500134D1 | B20: 134D1 | C20: 586688600-083 | D20: 46 | E20: 22 | F20: 56 | G20: 14 | H20: 28 | I20: 14 | J20: 14 | K20: 0 | L20: 0 | M20: 0 | N20: 0 | O20: 14 | P20: 0 | Q20: 0 | R20: 0 | S20: 0 | T20: 0 | U20: 0
A21: 546769500135D1 | B21: 135D1 | C21: 586688610-083 | D21: 12 | E21: 22 | F21: 0 | G21: 0 | H21: 0 | I21: 0 | J21: 0 | K21: 0 | L21: 0 | M21: 0 | N21: 0 | O21: 0 | P21: 0 | Q21: 0 | R21: 0 | S21: 0 | T21: 0 | U21: 0
A22: Customer Part No. | B22: Description | C22: Material Code | D22: Customer's Todays Plan | E22: CE open STK | F22: Total Plan | G22: Total Actual | H22: Vehicle Trip Plan | O22: Actual Dispatch
H23: T-1 | I23: T-2 | J23: T-3 | K23: T-4 | L23: T-5 | M23: T-6 | N23: T-7 | O23: T-1 | P23: T-2 | Q23: T-3 | R23: T-4 | S23: T-5 | T23: T-6 | U23: T-7
A25: 546469500102ZX | B25: 102ZX | C25: 587136190-083 | D25: 142 | E25: 12 | H25: 16 | I25: 32 | J25: 32 | K25: 32 | L25: 32 | M25: 0 | N25: 0 | O25: 12 | P25: 0 | Q25: 48 | R25: 0 | S25: 0 | T25: 0 | U25: 0 | W25: 60
A26: 546469500109ZY | B26: 109ZY | C26: 587136180-083 | D26: 19 | E26: 46 | F26: 32 | G26: 0 | H26: 0 | I26: 0 | J26: 16 | K26: 16 | L26: 0 | M26: 0 | O26: 0 | P26: 0 | Q26: 0 | R26: 0 | S26: 0 | T26: 0 | U26: 0 | W26: 0
A27: 546469500114ZY | B27: 114ZY | C27: 587011990-083 | D27: 208 | E27: 146 | F27: 160 | G27: 108 | H27: 48 | I27: 32 | J27: 16 | K27: 16 | L27: 48 | M27: 0 | O27: 48 | P27: 60 | Q27: 0 | R27: 0 | S27: 0 | T27: 0 | U27: 0 | W27: 108
A28: 546469500114ZZ | B28: 114ZZ | C28: 587011990-220 | D28: 103 | E28: 51 | F28: 80 | G28: 44 | H28: 16 | I28: 16 | J28: 16 | K28: 16 | L28: 16 | M28: 0 | O28: 12 | P28: 0 | Q28: 32 | R28: 0 | S28: 0 | T28: 0 | U28: 0 | W28: 44
A29: 546469500102ZZ | B29: 102ZZ | C29: 587136190-220 | D29: 48 | E29: 29 | F29: 64 | G29: 32 | H29: 16 | I29: 16 | J29: 16 | K29: 16 | L29: 0 | M29: 0 | O29: 16 | P29: 0 | Q29: 16 | R29: 0 | S29: 0 | T29: 0 | U29: 0 | W29: 32

Sheet 6-Sep (2)
F1: 45906 | M1: Vehicle Trip Plan | T1: Actual Dispatch | AE1: GAP
M2: T-1 | N2: T-2 | O2: T-3 | P2: T-4 | Q2: T-5 | R2: T-6 | T2: T-1 | U2: T-2 | V2: T-3 | W2: T-4 | X2: T-5 | Y2: T-6 | Z2: T-7 | AA2: T-8 | AB2: T=9 | AD2: Vehicle No. | AE2: T-1 | AF2: T-2 | AG2: T-3 | AH2: T-4 | AI2: T-5 | AJ2: T-6
A3: Customer Part No. | B3: Description | C3: Material Code | D3: Stocking Norm | E3: Customer's Todays Plan | F3: Stock at Customer End | G3: Stock on Wheel | H3: Dispatch Requirement | I3: Short against Requirement | J3: Total Plan | K3: Total Actual | L3: No Of Trolley | M3: 6 | N3: 6 | O3: 6 | P3: 6 | Q3: 6 | R3: 6 | S3: 36 | T3: 6 | U3: 3 | V3: 5 | W3: 4 | X3: 5 | Y3: 5 | AC3: 28 | AE3: 0 | AF3: -3 | AG3: -4 | AH3: 4 | AI3: -2 | AJ3: -8
L4: Vehicle No | AD4: Out Time
AD5: In time
L6: Time | M6: 0.27083333 | N6: 0.375 | O6: 0.5 | P6: 0.625 | Q6: 0.75 | R6: 0.875 | T6: 0.38888889 | U6: 0.38888889 | V6: 0.42361111 | W6: 0.5625 | X6: 0.70833333 | Y6: 0.82986111 | AD6: Actual | AE6: 0.27083333 | AF6: 0.29166667 | AG6: 0.40625 | AH6: 0.46875 | AI6: 0.61458333
A7: 542468900289ZZ | B7: Cluster GB | C7: 753000360-200 | D7: 184 | E7: 44 | F7: 77 | H7: 151 | I7: 55 | J7: 96 | K7: 0 | O7: 96 | AD7: 0 | AE7: 0 | AF7: 0 | AG7: -96 | AH7: -96 | AI7: -96 | AJ7: -96
A8: 542468900289ZV | B8: Cluster ULS | C8: 753000360-324 | D8: 199 | E8: 294 | F8: 120 | H8: 373 | I8: 0 | J8: 384 | K8: 288 | N8: 192 | O8: 96 | P8: 96 | V8: 192 | W8: 96 | AD8: 288 | AE8: 0 | AF8: -192 | AG8: -96 | AH8: -96 | AI8: -96 | AJ8: -96
A9: 542468900289ZQ | B9: Cluster Titan Brown | C9: 753000360-011 | D9: 168 | E9: 30 | F9: 100 | H9: 98 | I9: 2 | J9: 96 | K9: 96 | P9: 96 | Y9: 96 | AD9: 96 | AE9: 0 | AF9: 0 | AG9: 0 | AH9: 0 | AI9: 0 | AJ9: 0
A10: 542468910103CC | B10: Console LLG | C10: 753000370-009 | D10: 200 | E10: 12 | F10: 200 | H10: 12 | I10: 12 | J10: 0 | K10: 0 | AD10: 0 | AE10: 0 | AF10: 0 | AG10: 0 | AH10: 0 | AI10: 0 | AJ10: 0
A11: 542468910103D1 | B11: Console KLG | C11: 753000370-452 | D11: 260 | E11: 200 | F11: 130 | H11: 330 | I11: 0 | J11: 390 | K11: 260 | N11: 260 | P11: 130 | V11: 260 | AD11: 260 | AE11: 0 | AF11: -260 | AG11: 0 | AH11: -130 | AI11: -130 | AJ11: -130
A12: 542569500104D1 | B12: HMSL KLG | C12: 630131090-452 | D12: 140 | E12: 40 | F12: 150 | H12: 30 | I12: 30 | J12: 0 | K12: 0 | AD12: 0 | AE12: 0 | AF12: 0 | AG12: 0 | AH12: 0 | AI12: 0 | AJ12: 0
A13: 542569500104CC | B13: HMSL LLG | C13: 630131090 | D13: 140 | E13: 30 | F13: 60 | H13: 110 | I13: 0 | J13: 140 | K13: 0 | O13: 140 | AD13: 0 | AE13: 0 | AF13: 0 | AG13: -140 | AH13: -140 | AI13: -140 | AJ13: -140
A14: 542469500102D1 | B14: 102D1 | C14: 586118320-083 | D14: 42 | E14: 18 | F14: 48 | H14: 12 | I14: 0 | J14: 42 | K14: 28 | N14: 14 | Q14: 14 | R14: 14 | W14: 14 | Y14: 14 | AD14: 28 | AE14: 0 | AF14: -14 | AG14: -14 | AH14: 14 | AI14: 0 | AJ14: -14
A15: 542469500118D1 | B15: 118D1 | C15: 586688560-083 | D15: 28 | E15: 0 | F15: 32 | H15: 0 | I15: 0 | J15: 0 | K15: 0 | AD15: 0 | AE15: 0 | AF15: 0 | AG15: 0 | AH15: 0 | AI15: 0 | AJ15: 0
A16: 542469500119D1 | B16: 119D1 | C16: 586688570-083 | D16: 84 | E16: 299 | F16: 78 | H16: 305 | I16: 0 | J16: 378 | K16: 266 | M16: 84 | N16: 56 | O16: 56 | P16: 56 | Q16: 56 | R16: 70 | T16: 56 | U16: 56 | V16: 42 | W16: 28 | X16: 42 | Y16: 42 | AD16: 266 | AE16: -28 | AF16: -28 | AG16: -42 | AH16: 14 | AI16: -42 | AJ16: -112
A17: 542469500120D1 | B17: 120D1 | C17: 586450180-083 | D17: 28 | E17: 23 | F17: 42 | H17: 9 | I17: 0 | J17: 28 | K17: 28 | N17: 14 | Q17: 14 | W17: 14 | X17: 14 | AD17: 28 | AE17: 0 | AF17: -14 | AG17: -14 | AH17: 14 | AI17: 0 | AJ17: 0
A18: 546769500115D1 | B18: 115D1 | C18: 586688580-083 | D18: 0 | E18: 0 | F18: 0 | H18: 0 | I18: 0 | J18: 0 | K18: 0 | AD18: 0 | AE18: 0 | AF18: 0 | AG18: 0 | AH18: 0 | AI18: 0 | AJ18: 0
A19: 546769500133D1 | B19: 133D1 | C19: 586688590-083 | D19: 28 | E19: 0 | F19: 11 | H19: 17 | I19: 3 | J19: 14 | K19: 14 | O19: 14 | W19: 14 | AD19: 14 | AE19: 0 | AF19: 0 | AG19: -14 | AH19: 0 | AI19: 0 | AJ19: 0
A20: 546769500134D1 | B20: 134D1 | C20: 586688600-083 | D20: 28 | E20: 10 | F20: 30 | H20: 8 | I20: 0 | J20: 14 | K20: 14 | P20: 14 | X20: 14 | AD20: 14 | AE20: 0 | AF20: 0 | AG20: 0 | AH20: 0 | AI20: 0 | AJ20: 0
A21: 546769500135D1 | B21: 135D1 | C21: 586688610-083 | D21: 28 | E21: 9 | F21: 16 | H21: 21 | I21: 7 | J21: 14 | K21: 28 | P21: 14 | W21: 14 | Y21: 14 | AD21: 28 | AE21: 0 | AF21: 0 | AG21: 0 | AH21: 14 | AI21: 14 | AJ21: 14
A22: 542474700122 | B22: TAIL GATE | C22: 631161170-220 | D22: 50 | E22: 0 | F22: 55 | H22: 0 | I22: 0 | J22: 0 | K22: 0 | AD22: 0 | AE22: 0 | AF22: 0 | AG22: 0 | AH22: 0 | AI22: 0 | AJ22: 0
